Workbook

Sheet Instructions
A1: AURA ANDERMATT — 10-Year Financial Model
A3: HOW TO USE THIS MODEL
A5: This workbook contains a 10-year financial simulation (2027–2036) for Aura Andermatt.
A6: It consists of 4 working sheets: Dashboard, P&L, Revenue, and Cost.
A8: YELLOW CELLS = EDITABLE INPUTS
A10: All sheets are protected. Only yellow-highlighted cells can be edited.
A11: Yellow cells contain the key assumptions you can adjust:
A12: • Revenue sheet: ticket prices, guest counts, F&B spend, partnership values, growth rates
A13: • Cost sheet: individual cost items (venue, talent, security, etc.), overhead, founder pay
A14: • Dashboard: scenario adjustment factors (occupancy, price, partnership, ASA, costs, summer start)
A15: All other cells contain formulas that update automatically when you change inputs.
A17: UNLOCKING PROTECTED CELLS
... A71: • All currency values are in CHF.

Sheet Dashboard
A1: AURA ANDERMATT — DASHBOARD
A3: KEY METRICS | B3: Downside | C3: Base | D3: Upside
A4: 10-Year Cumulative Cash (CHF) | B4: =K32 -> 193941.09 | C4: =K20 -> 512904.47 | D4: =K44 -> 1255027.4
A5: 2027 Profit After Tax (CHF) | B5: =B31 -> -64369.272 | C5: =B19 -> -1314.135 | D5: =B43 -> 26018.202
A9: SCENARIO COMPARISON (10-YEAR P&L)
A10: BASE SCENARIO
B11: 2027 | C11: 2028 | D11: 2029 | E11: 2030 | F11: 2031 | G11: 2032 | H11: 2033 | I11: 2034 | J11: 2035 | K11: 2036
A12: Net Ticket Revenue | B12: ='P&L'!B10*$C$60*$C$61 -> 55625 | C12: ='P&L'!C10*$C$60*$C$61 -> 60075 | D12: ='P&L'!D10*$C$60*$C$61 -> 64881 | E12: ='P&L'!E10*$C$60*$C$61 -> 70071.48 | F12: ='P&L'!F10*$C$60*$C$61 -> 72874.339 | G12: ='P&L'!G10*$C$60*$C$61 -> 75789.313 | H12: ='P&L'!H10*$C$60*$C$61 -> 78820.885 | I12: ='P&L'!I10*$C$60*$C$61 -> 81973.721 | ... K12: ='P&L'!K10*$C$60*$C$61 -> 88662.776
A13: Partnership Revenue | B13: ='P&L'!B11*$C$62 -> 30000 | C13: ='P&L'!C11*$C$62 -> 55000 | D13: ='P&L'!D11*$C$62 -> 75000 | E13: ='P&L'!E11*$C$62 -> 95000 | F13: ='P&L'!F11*$C$62 -> 110000 | G13: ='P&L'!G11*$C$62 -> 116600 | H13: ='P&L'!H11*$C$62 -> 123596 | I13: ='P&L'!I11*$C$62 -> 131011.76 | ... K13: ='P&L'!K11*$C$62 -> 147204.81
A14: Other Revenue (ASA+F&B+Dinner+Other) | B14: ='P&L'!B12*$C$63+'P&L'!B13+'P&L'!B14+'P&L'!B15 -> 12640 | C14: ='P&L'!C12*$C$63+'P&L'!C13+'P&L'!C14+'P&L'!C15 -> 15199.2 | D14: ='P&L'!D12*$C$63+'P&L'!D13+'P&L'!D14+'P&L'!D15 -> 17759.776 | E14: ='P&L'!E12*$C$63+'P&L'!E13+'P&L'!E14+'P&L'!E15 -> 22821.761 | F14: ='P&L'!F12*$C$63+'P&L'!F13+'P&L'!F14+'P&L'!F15 -> 27885.19 | G14: ='P&L'!G12*$C$63+'P&L'!G13+'P&L'!G14+'P&L'!G15 -> 32950.097 | H14: ='P&L'!H12*$C$63+'P&L'!H13+'P&L'!H14+'P&L'!H15 -> 33016.518 | I14: ='P&L'!I12*$C$63+'P&L'!I13+'P&L'!I14+'P&L'!I15 -> 38084.491 | ... K14: ='P&L'!K12*$C$63+'P&L'!K13+'P&L'!K14+'P&L'!K15 -> 48225.24
A15: Total Revenue | B15: =(B12+B13+B14)*(1+IF(2027>=$C$71,Revenue!$B$11,0)) -> 152310.75 | C15: =(C12+C13+C14)*(1+IF(2028>=$C$71,Revenue!$B$11,0)) -> 201925.01 | D15: =(D12+D13+D14)*(1+IF(2029>=$C$71,Revenue!$B$11,0)) -> 244343.2 | E15: =(E12+E13+E14)*(1+IF(2030>=$C$71,Revenue!$B$11,0)) -> 291234.52 | F15: =(F12+F13+F14)*(1+IF(2031>=$C$71,Revenue!$B$11,0)) -> 326677.27 | G15: =(G12+G13+G14)*(1+IF(2032>=$C$71,Revenue!$B$11,0)) -> 349276.09 | H15: =(H12+H13+H14)*(1+IF(2033>=$C$71,Revenue!$B$11,0)) -> 364921.78 | I15: =(I12+I13+I14)*(1+IF(2034>=$C$71,Revenue!$B$11,0)) -> 389158.46 | J15: =(J12+J13+J14)*(1+IF(2035>=$C$71,Revenue!$B$11,0)) -> 414282.74 | K15: =(K12+K13+K14)*(1+IF(2036>=$C$71,Revenue!$B$11,0)) -> 440343.89
A16: Total Costs | B16: ='P&L'!B20*$C$66+'P&L'!B21+'P&L'!B22*$C$67 -> -153624.89 | C16: ='P&L'!C20*$C$66+'P&L'!C21+'P&L'!C22*$C$67 -> -169557.53 | D16: ='P&L'!D20*$C$66+'P&L'!D21+'P&L'!D22*$C$67 -> -185810.4 | E16: ='P&L'!E20*$C$66+'P&L'!E21+'P&L'!E22*$C$67 -> -243401.72 | F16: ='P&L'!F20*$C$66+'P&L'!F21+'P&L'!F22*$C$67 -> -270350.76 | G16: ='P&L'!G20*$C$66+'P&L'!G21+'P&L'!G22*$C$67 -> -280477.95 | H16: ='P&L'!H20*$C$66+'P&L'!H21+'P&L'!H22*$C$67 -> -307116.89 | I16: ='P&L'!I20*$C$66+'P&L'!I21+'P&L'!I22*$C$67 -> -319294.92 | ... K16: ='P&L'!K20*$C$66+'P&L'!K21+'P&L'!K22*$C$67 -> -347385.42
A17: EBIT | B17: =B15+B16 -> -1314.135 | C17: =C15+C16 -> 32367.478 | D17: =D15+D16 -> 58532.8 | E17: =E15+E16 -> 47832.806 | F17: =F15+F16 -> 56326.508 | G17: =G15+G16 -> 68798.136 | H17: =H15+H16 -> 57804.89 | I17: =I15+I16 -> 69863.531 | ... K17: =K15+K16 -> 92958.471
A18: Tax | B18: =IF(B17>0,-B17*'P&L'!$B$5,0) -> 0 | C18: =IF(C17>0,-C17*'P&L'!$B$5,0) -> -4091.2493 | D18: =IF(D17>0,-D17*'P&L'!$B$5,0) -> -7398.546 | E18: =IF(E17>0,-E17*'P&L'!$B$5,0) -> -6046.0667 | F18: =IF(F17>0,-F17*'P&L'!$B$5,0) -> -7119.6706 | G18: =IF(G17>0,-G17*'P&L'!$B$5,0) -> -8696.0844 | H18: =IF(H17>0,-H17*'P&L'!$B$5,0) -> -7306.5382 | I18: =IF(I17>0,-I17*'P&L'!$B$5,0) -> -8830.7503 | ... K18: =IF(K17>0,-K17*'P&L'!$B$5,0) -> -11749.951
A19: Profit After Tax | B19: =B17+B18 -> -1314.135 | C19: =C17+C18 -> 28276.229 | D19: =D17+D18 -> 51134.254 | E19: =E17+E18 -> 41786.74 | F19: =F17+F18 -> 49206.837 | G19: =G17+G18 -> 60102.052 | H19: =H17+H18 -> 50498.352 | I19: =I17+I18 -> 61032.78 | ... K19: =K17+K18 -> 81208.52
A20: Cumulative Cash | B20: ='P&L'!$B$6+B19 -> 18685.865 | C20: =B20+C19 -> 46962.094 | D20: =C20+D19 -> 98096.349 | E20: =D20+E19 -> 139883.09 | F20: =E20+F19 -> 189089.93 | G20: =F20+G19 -> 249191.98 | H20: =G20+H19 -> 299690.33 | I20: =H20+I19 -> 360723.11 | J20: =I20+J19 -> 431695.94 | K20: =J20+K19 -> 512904.47
A22: DOWNSIDE SCENARIO
B23: 2027 | C23: 2028 | D23: 2029 | E23: 2030 | F23: 2031 | G23: 2032 | H23: 2033 | I23: 2034 | J23: 2035 | K23: 2036
A24: Net Ticket Revenue (adj.) | B24: ='P&L'!B10*$B$60*$B$61 -> 42553.125 | C24: ='P&L'!C10*$B$60*$B$61 -> 45957.375 | D24: ='P&L'!D10*$B$60*$B$61 -> 49633.965 | E24: ='P&L'!E10*$B$60*$B$61 -> 53604.682 | F24: ='P&L'!F10*$B$60*$B$61 -> 55748.869 | G24: ='P&L'!G10*$B$60*$B$61 -> 57978.824 | H24: ='P&L'!H10*$B$60*$B$61 -> 60297.977 | I24: ='P&L'!I10*$B$60*$B$61 -> 62709.896 | ... K24: ='P&L'!K10*$B$60*$B$61 -> 67827.024
A25: Partnership Revenue (adj.) | B25: ='P&L'!B11*$B$62 -> 18000 | C25: ='P&L'!C11*$B$62 -> 33000 | D25: ='P&L'!D11*$B$62 -> 45000 | E25: ='P&L'!E11*$B$62 -> 57000 | F25: ='P&L'!F11*$B$62 -> 66000 | G25: ='P&L'!G11*$B$62 -> 69960 | H25: ='P&L'!H11*$B$62 -> 74157.6 | I25: ='P&L'!I11*$B$62 -> 78607.056 | ... K25: ='P&L'!K11*$B$62 -> 88322.888
A26: Other Revenue (ASA+F&B+Dinner+Other) (adj.) | B26: ='P&L'!B12*$B$63+'P&L'!B13+'P&L'!B14+'P&L'!B15 -> 10140 | C26: ='P&L'!C12*$B$63+'P&L'!C13+'P&L'!C14+'P&L'!C15 -> 12074.2 | D26: ='P&L'!D12*$B$63+'P&L'!D13+'P&L'!D14+'P&L'!D15 -> 14009.776 | E26: ='P&L'!E12*$B$63+'P&L'!E13+'P&L'!E14+'P&L'!E15 -> 17821.761 | F26: ='P&L'!F12*$B$63+'P&L'!F13+'P&L'!F14+'P&L'!F15 -> 21635.19 | G26: ='P&L'!G12*$B$63+'P&L'!G13+'P&L'!G14+'P&L'!G15 -> 25450.097 | H26: ='P&L'!H12*$B$63+'P&L'!H13+'P&L'!H14+'P&L'!H15 -> 25516.518 | I26: ='P&L'!I12*$B$63+'P&L'!I13+'P&L'!I14+'P&L'!I15 -> 29334.491 | ... K26: ='P&L'!K12*$B$63+'P&L'!K13+'P&L'!K14+'P&L'!K15 -> 36975.24
A27: Total Revenue | B27: =(B24+B25+B26)*(1+IF(2027>=$B$71,Revenue!$B$11,0)) -> 70693.125 | C27: =(C24+C25+C26)*(1+IF(2028>=$B$71,Revenue!$B$11,0)) -> 91031.575 | D27: =(D24+D25+D26)*(1+IF(2029>=$B$71,Revenue!$B$11,0)) -> 168397.8 | E27: =(E24+E25+E26)*(1+IF(2030>=$B$71,Revenue!$B$11,0)) -> 199060.99 | F27: =(F24+F25+F26)*(1+IF(2031>=$B$71,Revenue!$B$11,0)) -> 222245.29 | G27: =(G24+G25+G26)*(1+IF(2032>=$B$71,Revenue!$B$11,0)) -> 237752.83 | H27: =(H24+H25+H26)*(1+IF(2033>=$B$71,Revenue!$B$11,0)) -> 247956.75 | I27: =(I24+I25+I26)*(1+IF(2034>=$B$71,Revenue!$B$11,0)) -> 264509.74 | J27: =(J24+J25+J26)*(1+IF(2035>=$B$71,Revenue!$B$11,0)) -> 281628.53 | K27: =(K24+K25+K26)*(1+IF(2036>=$B$71,Revenue!$B$11,0)) -> 299343.99
A28: Total Costs (adj.) | B28: ='P&L'!B20*$B$66-$B$68+'P&L'!B22*$B$67 -> -135062.4 | C28: ='P&L'!C20*$B$66-$B$68+'P&L'!C22*$B$67 -> -145401.78 | D28: ='P&L'!D20*$B$66-$B$68+'P&L'!D22*$B$67 -> -156029.36 | E28: ='P&L'!E20*$B$66-$B$68+'P&L'!E22*$B$67 -> -171961.55 | F28: ='P&L'!F20*$B$66-$B$68+'P&L'!F22*$B$67 -> -188215.69 | G28: ='P&L'!G20*$B$66-$B$68+'P&L'!G22*$B$67 -> -196210.15 | H28: ='P&L'!H20*$B$66-$B$68+'P&L'!H22*$B$67 -> -204620.4 | I28: ='P&L'!I20*$B$66-$B$68+'P&L'!I22*$B$67 -> -213469.24 | ... K28: ='P&L'!K20*$B$66-$B$68+'P&L'!K22*$B$67 -> -232580.59
A29: EBIT | B29: =B27+B28 -> -64369.272 | C29: =C27+C28 -> -54370.203 | D29: =D27+D28 -> 12368.436 | E29: =E27+E28 -> 27099.441 | F29: =F27+F28 -> 34029.606 | G29: =G27+G28 -> 41542.674 | H29: =H27+H28 -> 43336.352 | I29: =I27+I28 -> 51040.496 | ... K29: =K27+K28 -> 66763.393
A30: Tax | B30: =IF(B29>0,-B29*'P&L'!$B$5,0) -> 0 | C30: =IF(C29>0,-C29*'P&L'!$B$5,0) -> 0 | D30: =IF(D29>0,-D29*'P&L'!$B$5,0) -> -1563.3703 | E30: =IF(E29>0,-E29*'P&L'!$B$5,0) -> -3425.3694 | F30: =IF(F29>0,-F29*'P&L'!$B$5,0) -> -4301.3422 | G30: =IF(G29>0,-G29*'P&L'!$B$5,0) -> -5250.994 | H30: =IF(H29>0,-H29*'P&L'!$B$5,0) -> -5477.7148 | I30: =IF(I29>0,-I29*'P&L'!$B$5,0) -> -6451.5187 | ... K30: =IF(K29>0,-K29*'P&L'!$B$5,0) -> -8438.8929
A31: Profit After Tax | B31: =B29+B30 -> -64369.272 | C31: =C29+C30 -> -54370.203 | D31: =D29+D30 -> 10805.066 | E31: =E29+E30 -> 23674.072 | F31: =F29+F30 -> 29728.264 | G31: =G29+G30 -> 36291.68 | H31: =H29+H30 -> 37858.637 | I31: =I29+I30 -> 44588.977 | ... K31: =K29+K30 -> 58324.5
A32: Cumulative Cash | B32: ='P&L'!$B$6+B31 -> -44369.272 | C32: =B32+C31 -> -98739.475 | D32: =C32+D31 -> -87934.409 | E32: =D32+E31 -> -64260.337 | F32: =E32+F31 -> -34532.073 | G32: =F32+G31 -> 1759.6072 | H32: =G32+H31 -> 39618.244 | I32: =H32+I31 -> 84207.221 | J32: =I32+J31 -> 135616.59 | K32: =J32+K31 -> 193941.09
A34: UPSIDE SCENARIO
B35: 2027 | C35: 2028 | D35: 2029 | E35: 2030 | F35: 2031 | G35: 2032 | H35: 2033 | I35: 2034 | J35: 2035 | K35: 2036
A36: Net Ticket Revenue (adj.) | B36: ='P&L'!B10*$D$60*$D$61 -> 61187.5 | C36: ='P&L'!C10*$D$60*$D$61 -> 66082.5 | D36: ='P&L'!D10*$D$60*$D$61 -> 71369.1 | E36: ='P&L'!E10*$D$60*$D$61 -> 77078.628 | F36: ='P&L'!F10*$D$60*$D$61 -> 80161.773 | G36: ='P&L'!G10*$D$60*$D$61 -> 83368.244 | H36: ='P&L'!H10*$D$60*$D$61 -> 86702.974 | I36: ='P&L'!I10*$D$60*$D$61 -> 90171.093 | ... K36: ='P&L'!K10*$D$60*$D$61 -> 97529.054
A37: Partnership Revenue (adj.) | B37: ='P&L'!B11*$D$62 -> 42000 | C37: ='P&L'!C11*$D$62 -> 77000 | D37: ='P&L'!D11*$D$62 -> 105000 | E37: ='P&L'!E11*$D$62 -> 133000 | F37: ='P&L'!F11*$D$62 -> 154000 | G37: ='P&L'!G11*$D$62 -> 163240 | H37: ='P&L'!H11*$D$62 -> 173034.4 | I37: ='P&L'!I11*$D$62 -> 183416.46 | ... K37: ='P&L'!K11*$D$62 -> 206086.74
A38: Other Revenue (ASA+F&B+Dinner+Other) (adj.) | B38: ='P&L'!B12*$D$63+'P&L'!B13+'P&L'!B14+'P&L'!B15 -> 15140 | C38: ='P&L'!C12*$D$63+'P&L'!C13+'P&L'!C14+'P&L'!C15 -> 18324.2 | D38: ='P&L'!D12*$D$63+'P&L'!D13+'P&L'!D14+'P&L'!D15 -> 21509.776 | E38: ='P&L'!E12*$D$63+'P&L'!E13+'P&L'!E14+'P&L'!E15 -> 27821.761 | F38: ='P&L'!F12*$D$63+'P&L'!F13+'P&L'!F14+'P&L'!F15 -> 34135.19 | G38: ='P&L'!G12*$D$63+'P&L'!G13+'P&L'!G14+'P&L'!G15 -> 40450.097 | H38: ='P&L'!H12*$D$63+'P&L'!H13+'P&L'!H14+'P&L'!H15 -> 40516.518 | I38: ='P&L'!I12*$D$63+'P&L'!I13+'P&L'!I14+'P&L'!I15 -> 46834.491 | ... K38: ='P&L'!K12*$D$63+'P&L'!K13+'P&L'!K14+'P&L'!K15 -> 59475.24
A39: Total Revenue | B39: =(B36+B37+B38)*(1+IF(2027>=$D$71,Revenue!$B$11,0)) -> 183407.62 | C39: =(C36+C37+C38)*(1+IF(2028>=$D$71,Revenue!$B$11,0)) -> 250180.39 | D39: =(D36+D37+D38)*(1+IF(2029>=$D$71,Revenue!$B$11,0)) -> 306712.26 | E39: =(E36+E37+E38)*(1+IF(2030>=$D$71,Revenue!$B$11,0)) -> 368745.6 | F39: =(F36+F37+F38)*(1+IF(2031>=$D$71,Revenue!$B$11,0)) -> 415860.29 | G39: =(G36+G37+G38)*(1+IF(2032>=$D$71,Revenue!$B$11,0)) -> 444940.43 | H39: =(H36+H37+H38)*(1+IF(2033>=$D$71,Revenue!$B$11,0)) -> 465393.53 | I39: =(I36+I37+I38)*(1+IF(2034>=$D$71,Revenue!$B$11,0)) -> 496654.17 | J39: =(J36+J37+J38)*(1+IF(2035>=$D$71,Revenue!$B$11,0)) -> 529097.83 | K39: =(K36+K37+K38)*(1+IF(2036>=$D$71,Revenue!$B$11,0)) -> 562791.1
A40: Total Costs (adj.) | B40: ='P&L'!B20*$D$66+'P&L'!B21+'P&L'!B22*$D$67 -> -153624.89 | C40: ='P&L'!C20*$D$66+'P&L'!C21+'P&L'!C22*$D$67 -> -169557.53 | D40: ='P&L'!D20*$D$66+'P&L'!D21+'P&L'!D22*$D$67 -> -185810.4 | E40: ='P&L'!E20*$D$66+'P&L'!E21+'P&L'!E22*$D$67 -> -243401.72 | F40: ='P&L'!F20*$D$66+'P&L'!F21+'P&L'!F22*$D$67 -> -270350.76 | G40: ='P&L'!G20*$D$66+'P&L'!G21+'P&L'!G22*$D$67 -> -280477.95 | H40: ='P&L'!H20*$D$66+'P&L'!H21+'P&L'!H22*$D$67 -> -307116.89 | I40: ='P&L'!I20*$D$66+'P&L'!I21+'P&L'!I22*$D$67 -> -319294.92 | ... K40: ='P&L'!K20*$D$66+'P&L'!K21+'P&L'!K22*$D$67 -> -347385.42
A41: EBIT | B41: =B39+B40 -> 29782.74 | C41: =C39+C40 -> 80622.853 | D41: =D39+D40 -> 120901.86 | E41: =E39+E40 -> 125343.89 | F41: =F39+F40 -> 145509.53 | G41: =G39+G40 -> 164462.48 | H41: =H39+H40 -> 158276.65 | I41: =I39+I40 -> 177359.25 | ... K41: =K39+K40 -> 215405.69
A42: Tax | B42: =IF(B41>0,-B41*'P&L'!$B$5,0) -> -3764.5383 | C42: =IF(C41>0,-C41*'P&L'!$B$5,0) -> -10190.729 | D42: =IF(D41>0,-D41*'P&L'!$B$5,0) -> -15281.995 | E42: =IF(E41>0,-E41*'P&L'!$B$5,0) -> -15843.467 | F42: =IF(F41>0,-F41*'P&L'!$B$5,0) -> -18392.405 | G42: =IF(G41>0,-G41*'P&L'!$B$5,0) -> -20788.057 | H42: =IF(H41>0,-H41*'P&L'!$B$5,0) -> -20006.168 | I42: =IF(I41>0,-I41*'P&L'!$B$5,0) -> -22418.209 | ... K42: =IF(K41>0,-K41*'P&L'!$B$5,0) -> -27227.279
A43: Profit After Tax | B43: =B41+B42 -> 26018.202 | C43: =C41+C42 -> 70432.125 | D43: =D41+D42 -> 105619.86 | E43: =E41+E42 -> 109500.42 | F43: =F41+F42 -> 127117.13 | G43: =G41+G42 -> 143674.42 | H43: =H41+H42 -> 138270.48 | I43: =I41+I42 -> 154941.04 | ... K43: =K41+K42 -> 188178.41
A44: Cumulative Cash | B44: ='P&L'!$B$6+B43 -> 46018.202 | C44: =B44+C43 -> 116450.33 | D44: =C44+D43 -> 222070.19 | E44: =D44+E43 -> 331570.61 | F44: =E44+F43 -> 458687.73 | G44: =F44+G43 -> 602362.15 | H44: =G44+H43 -> 740632.63 | I44: =H44+I43 -> 895573.67 | J44: =I44+J43 -> 1066849 | K44: =J44+K43 -> 1255027.4
A55: SCENARIO ADJUSTMENTS (change values below to adjust scenarios)
B56: Downside | C56: Base | D56: Upside
...

Sheet P&L
A1: PROFIT & LOSS
A3: EXTERNAL PARAMETERS (normally do not change)
A4: General Inflation Rate | B4: 0.02
A5: Tax Rate (Uri canton combined) | B5: 0.1264
A6: Initial Capital (GmbH paid-in) | B6: 20000
A8: 10-YEAR PROFIT & LOSS
B9: 2027 | C9: 2028 | D9: 2029 | E9: 2030 | F9: 2031 | G9: 2032 | H9: 2033 | I9: 2034 | J9: 2035 | K9: 2036
A10: Net Ticket Revenue | B10: =Revenue!B40 -> 55625 | C10: =Revenue!C40 -> 60075 | D10: =Revenue!D40 -> 64881 | E10: =Revenue!E40 -> 70071.48 | F10: =Revenue!F40 -> 72874.339 | G10: =Revenue!G40 -> 75789.313 | H10: =Revenue!H40 -> 78820.885 | I10: =Revenue!I40 -> 81973.721 | ... K10: =Revenue!K40 -> 88662.776
A11: Partnership Revenue | B11: =Revenue!B56 -> 30000 | C11: =Revenue!C56 -> 55000 | D11: =Revenue!D56 -> 75000 | E11: =Revenue!E56 -> 95000 | F11: =Revenue!F56 -> 110000 | G11: =Revenue!G56 -> 116600 | H11: =Revenue!H56 -> 123596 | I11: =Revenue!I56 -> 131011.76 | ... K11: =Revenue!K56 -> 147204.81
A12: ASA Contribution | B12: =Revenue!B61 -> 10000 | C12: =Revenue!C61 -> 12500 | D12: =Revenue!D61 -> 15000 | E12: =Revenue!E61 -> 20000 | F12: =Revenue!F61 -> 25000 | G12: =Revenue!G61 -> 30000 | H12: =Revenue!H61 -> 30000 | I12: =Revenue!I61 -> 35000 | ... K12: =Revenue!K61 -> 45000
A13: Bar/F&B Revenue | B13: =Revenue!B98 -> 640 | C13: =Revenue!C98 -> 659.2 | D13: =Revenue!D98 -> 678.976 | E13: =Revenue!E98 -> 699.34528 | F13: =Revenue!F98 -> 720.32564 | G13: =Revenue!G98 -> 741.93541 | H13: =Revenue!H98 -> 764.19347 | I13: =Revenue!I98 -> 787.11927 | ... K13: =Revenue!K98 -> 835.05484
A14: Dinner Revenue | B14: =Revenue!B102 -> 0 | C14: =Revenue!C102 -> 0 | D14: =Revenue!D102 -> 0 | E14: =Revenue!E102 -> 0 | F14: =Revenue!F102 -> 0 | G14: =Revenue!G102 -> 0 | H14: =Revenue!H102 -> 0 | I14: =Revenue!I102 -> 0 | ... K14: =Revenue!K102 -> 0
A15: Other Revenue | B15: =Revenue!B107 -> 2000 | C15: =Revenue!C107 -> 2040 | D15: =Revenue!D107 -> 2080.8 | E15: =Revenue!E107 -> 2122.416 | F15: =Revenue!F107 -> 2164.8643 | G15: =Revenue!G107 -> 2208.1616 | H15: =Revenue!H107 -> 2252.3248 | I15: =Revenue!I107 -> 2297.3713 | ... K15: =Revenue!K107 -> 2390.1851
A17: TOTAL REVENUE | B17: =Revenue!B114 -> 152310.75 | C17: =Revenue!C114 -> 201925.01 | D17: =Revenue!D114 -> 244343.2 | E17: =Revenue!E114 -> 291234.52 | F17: =Revenue!F114 -> 326677.27 | G17: =Revenue!G114 -> 349276.09 | H17: =Revenue!H114 -> 364921.78 | I17: =Revenue!I114 -> 389158.46 | ... K17: =Revenue!K114 -> 440343.89
A19: Costs
A20: Total Direct Costs | B20: =-Cost!B49 -> -135624.89 | C20: =-Cost!C49 -> -141557.53 | D20: =-Cost!D49 -> -147810.4 | E20: =-Cost!E49 -> -154401.72 | F20: =-Cost!F49 -> -161350.76 | G20: =-Cost!G49 -> -168677.95 | H20: =-Cost!H49 -> -176404.89 | I20: =-Cost!I49 -> -184554.44 | ... K20: =-Cost!K49 -> -202219.71
A21: Overhead | B21: =-Cost!B53 -> -8000 | C21: =-Cost!C53 -> -8000 | D21: =-Cost!D53 -> -8000 | E21: =-Cost!E53 -> -39000 | F21: =-Cost!F53 -> -39000 | G21: =-Cost!G53 -> -39000 | H21: =-Cost!H53 -> -55000 | I21: =-Cost!I53 -> -56000 | ... K21: =-Cost!K53 -> -60000
A22: Founder Pay | B22: =-Cost!B55 -> -10000 | C22: =-Cost!C55 -> -20000 | D22: =-Cost!D55 -> -30000 | E22: =-Cost!E55 -> -50000 | F22: =-Cost!F55 -> -70000 | G22: =-Cost!G55 -> -72800 | H22: =-Cost!H55 -> -75712 | I22: =-Cost!I55 -> -78740.48 | ... K22: =-Cost!K55 -> -85165.703
A24: TOTAL COSTS | B24: =B20+B21+B22 -> -153624.89 | C24: =C20+C21+C22 -> -169557.53 | D24: =D20+D21+D22 -> -185810.4 | E24: =E20+E21+E22 -> -243401.72 | F24: =F20+F21+F22 -> -270350.76 | G24: =G20+G21+G22 -> -280477.95 | H24: =H20+H21+H22 -> -307116.89 | I24: =I20+I21+I22 -> -319294.92 | ... K24: =K20+K21+K22 -> -347385.42
A26: RESULTS
A27: EBIT | B27: =B17+B24 -> -1314.135 | C27: =C17+C24 -> 32367.478 | D27: =D17+D24 -> 58532.8 | E27: =E17+E24 -> 47832.806 | F27: =F17+F24 -> 56326.508 | G27: =G17+G24 -> 68798.136 | H27: =H17+H24 -> 57804.89 | I27: =I17+I24 -> 69863.531 | ... K27: =K17+K24 -> 92958.471
A28: Tax | B28: =IF(B27>0,-B27*$B$5,0) -> 0 | C28: =IF(C27>0,-C27*$B$5,0) -> -4091.2493 | D28: =IF(D27>0,-D27*$B$5,0) -> -7398.546 | E28: =IF(E27>0,-E27*$B$5,0) -> -6046.0667 | F28: =IF(F27>0,-F27*$B$5,0) -> -7119.6706 | G28: =IF(G27>0,-G27*$B$5,0) -> -8696.0844 | H28: =IF(H27>0,-H27*$B$5,0) -> -7306.5382 | I28: =IF(I27>0,-I27*$B$5,0) -> -8830.7503 | ... K28: =IF(K27>0,-K27*$B$5,0) -> -11749.951
A29: PROFIT AFTER TAX | B29: =B27+B28 -> -1314.135 | C29: =C27+C28 -> 28276.229 | D29: =D27+D28 -> 51134.254 | E29: =E27+E28 -> 41786.74 | F29: =F27+F28 -> 49206.837 | G29: =G27+G28 -> 60102.052 | H29: =H27+H28 -> 50498.352 | I29: =I27+I28 -> 61032.78 | ... K29: =K27+K28 -> 81208.52
A30: CUMULATIVE CASH | B30: =$B$6+B29 -> 18685.865 | C30: =B30+C29 -> 46962.094 | D30: =C30+D29 -> 98096.349 | E30: =D30+E29 -> 139883.09 | F30: =E30+F29 -> 189089.93 | G30: =F30+G29 -> 249191.98 | H30: =G30+H29 -> 299690.33 | I30: =H30+I29 -> 360723.11 | J30: =I30+J29 -> 431695.94 | K30: =J30+K29 -> 512904.47

Sheet Revenue
A1: REVENUE
A3: MODEL ASSUMPTIONS
A4: Total Guest Count | B4: 280
A5: Total Ticket Count | B5: 250
A6: Net Factor (VAT + platform fees) | B6: 0.89
A7: Ticket Price Growth Rate (to 2030) | B7: 0.08
A8: Ticket Price Growth Rate (2031+) | B8: 0.04
A9: F&B Growth Rate | B9: 0.03
A10: Partnership Growth Rate (2032+) | B10: 0.06
A11: Summer Revenue Multiplier | B11: 0.55
A12: Summer Cost Multiplier | B12: 0.5
A13: Summer Start Year | B13: 2027
A15: SECTION 1: TICKET REVENUE
A16: Drop Allocation
A17: Drop 1 Allocation % | B17: 0.28
A18: Drop 2 Allocation % | B18: 0.44
A19: Drop 3 Allocation % | B19: 0.28
A21: 2027 Base Prices (CHF)
A22: Drop 1 Unit Price | B22: 210
A23: Drop 2 Unit Price | B23: 250
A24: Drop 3 Unit Price | B24: 290
A26: 10-YEAR TICKET PROJECTION
B27: 2027 | C27: 2028 | D27: 2029 | E27: 2030 | F27: 2031 | G27: 2032 | H27: 2033 | I27: 2034 | J27: 2035 | K27: 2036
A28: Drop 1 Quantity | B28: =ROUND($B$5*$B$17,0) -> 70 | C28: =ROUND($B$5*$B$17,0) -> 70 | D28: =ROUND($B$5*$B$17,0) -> 70 | E28: =ROUND($B$5*$B$17,0) -> 70 | F28: =ROUND($B$5*$B$17,0) -> 70 | G28: =ROUND($B$5*$B$17,0) -> 70 | H28: =ROUND($B$5*$B$17,0) -> 70 | I28: =ROUND($B$5*$B$17,0) -> 70 | ... K28: =ROUND($B$5*$B$17,0) -> 70
A29: Drop 2 Quantity | B29: =ROUND($B$5*$B$18,0) -> 110 | C29: =ROUND($B$5*$B$18,0) -> 110 | D29: =ROUND($B$5*$B$18,0) -> 110 | E29: =ROUND($B$5*$B$18,0) -> 110 | F29: =ROUND($B$5*$B$18,0) -> 110 | G29: =ROUND($B$5*$B$18,0) -> 110 | H29: =ROUND($B$5*$B$18,0) -> 110 | I29: =ROUND($B$5*$B$18,0) -> 110 | ... K29: =ROUND($B$5*$B$18,0) -> 110
A30: Drop 3 Quantity | B30: =ROUND($B$5*$B$19,0) -> 70 | C30: =ROUND($B$5*$B$19,0) -> 70 | D30: =ROUND($B$5*$B$19,0) -> 70 | E30: =ROUND($B$5*$B$19,0) -> 70 | F30: =ROUND($B$5*$B$19,0) -> 70 | G30: =ROUND($B$5*$B$19,0) -> 70 | H30: =ROUND($B$5*$B$19,0) -> 70 | I30: =ROUND($B$5*$B$19,0) -> 70 | ... K30: =ROUND($B$5*$B$19,0) -> 70
A32: Drop 1 Price (CHF) | B32: =$B$22 -> 210 | C32: =IF(2028<=2030,B32*(1+$B$7),B32*(1+$B$8)) -> 226.8 | D32: =IF(2029<=2030,C32*(1+$B$7),C32*(1+$B$8)) -> 244.944 | E32: =IF(2030<=2030,D32*(1+$B$7),D32*(1+$B$8)) -> 264.53952 | F32: =IF(2031<=2030,E32*(1+$B$7),E32*(1+$B$8)) -> 275.1211 | G32: =IF(2032<=2030,F32*(1+$B$7),F32*(1+$B$8)) -> 286.12594 | H32: =IF(2033<=2030,G32*(1+$B$7),G32*(1+$B$8)) -> 297.57098 | I32: =IF(2034<=2030,H32*(1+$B$7),H32*(1+$B$8)) -> 309.47382 | J32: =IF(2035<=2030,I32*(1+$B$7),I32*(1+$B$8)) -> 321.85277 | K32: =IF(2036<=2030,J32*(1+$B$7),J32*(1+$B$8)) -> 334.72689
A33: Drop 2 Price (CHF) | B33: =$B$23 -> 250 | C33: =IF(2028<=2030,B33*(1+$B$7),B33*(1+$B$8)) -> 270 | D33: =IF(2029<=2030,C33*(1+$B$7),C33*(1+$B$8)) -> 291.6 | E33: =IF(2030<=2030,D33*(1+$B$7),D33*(1+$B$8)) -> 314.928 | F33: =IF(2031<=2030,E33*(1+$B$7),E33*(1+$B$8)) -> 327.52512 | G33: =IF(2032<=2030,F33*(1+$B$7),F33*(1+$B$8)) -> 340.62612 | H33: =IF(2033<=2030,G33*(1+$B$7),G33*(1+$B$8)) -> 354.25117 | I33: =IF(2034<=2030,H33*(1+$B$7),H33*(1+$B$8)) -> 368.42122 | J33: =IF(2035<=2030,I33*(1+$B$7),I33*(1+$B$8)) -> 383.15807 | K33: =IF(2036<=2030,J33*(1+$B$7),J33*(1+$B$8)) -> 398.48439
A34: Drop 3 Price (CHF) | B34: =$B$24 -> 290 | C34: =IF(2028<=2030,B34*(1+$B$7),B34*(1+$B$8)) -> 313.2 | D34: =IF(2029<=2030,C34*(1+$B$7),C34*(1+$B$8)) -> 338.256 | E34: =IF(2030<=2030,D34*(1+$B$7),D34*(1+$B$8)) -> 365.31648 | F34: =IF(2031<=2030,E34*(1+$B$7),E34*(1+$B$8)) -> 379.92914 | G34: =IF(2032<=2030,F34*(1+$B$7),F34*(1+$B$8)) -> 395.1263 | H34: =IF(2033<=2030,G34*(1+$B$7),G34*(1+$B$8)) -> 410.93136 | I34: =IF(2034<=2030,H34*(1+$B$7),H34*(1+$B$8)) -> 427.36861 | J34: =IF(2035<=2030,I34*(1+$B$7),I34*(1+$B$8)) -> 444.46336 | K34: =IF(2036<=2030,J34*(1+$B$7),J34*(1+$B$8)) -> 462.24189
A36: Drop 1 Revenue | B36: =B28*B32 -> 14700 | C36: =C28*C32 -> 15876 | D36: =D28*D32 -> 17146.08 | E36: =E28*E32 -> 18517.766 | F36: =F28*F32 -> 19258.477 | G36: =G28*G32 -> 20028.816 | H36: =H28*H32 -> 20829.969 | I36: =I28*I32 -> 21663.168 | ... K36: =K28*K32 -> 23430.882
A37: Drop 2 Revenue | B37: =B29*B33 -> 27500 | C37: =C29*C33 -> 29700 | D37: =D29*D33 -> 32076 | E37: =E29*E33 -> 34642.08 | F37: =F29*F33 -> 36027.763 | G37: =G29*G33 -> 37468.874 | H37: =H29*H33 -> 38967.629 | I37: =I29*I33 -> 40526.334 | ... K37: =K29*K33 -> 43833.283
A38: Drop 3 Revenue | B38: =B30*B34 -> 20300 | C38: =C30*C34 -> 21924 | D38: =D30*D34 -> 23677.92 | E38: =E30*E34 -> 25572.154 | F38: =F30*F34 -> 26595.04 | G38: =G30*G34 -> 27658.841 | H38: =H30*H34 -> 28765.195 | I38: =I30*I34 -> 29915.803 | ... K38: =K30*K34 -> 32356.932
A39: Gross Ticket Revenue | B39: =B36+B37+B38 -> 62500 | C39: =C36+C37+C38 -> 67500 | D39: =D36+D37+D38 -> 72900 | E39: =E36+E37+E38 -> 78732 | F39: =F36+F37+F38 -> 81881.28 | G39: =G36+G37+G38 -> 85156.531 | H39: =H36+H37+H38 -> 88562.792 | I39: =I36+I37+I38 -> 92105.304 | ... K39: =K36+K37+K38 -> 99621.097
A40: Net Ticket Revenue | B40: =B39*$B$6 -> 55625 | C40: =C39*$B$6 -> 60075 | D40: =D39*$B$6 -> 64881 | E40: =E39*$B$6 -> 70071.48 | F40: =F39*$B$6 -> 72874.339 | G40: =G39*$B$6 -> 75789.313 | H40: =H39*$B$6 -> 78820.885 | I40: =I39*$B$6 -> 81973.721 | ... K40: =K39*$B$6 -> 88662.776
A42: SECTION 2: PARTNERSHIPS
B43: 2027 | C43: 2028 | D43: 2029 | E43: 2030 | F43: 2031 | G43: 2032 | H43: 2033 | I43: 2034 | J43: 2035 | K43: 2036
A44: Presenting Partner — Price | B44: 0 | C44: 50000 | D44: 50000 | E44: 50000 | F44: 50000
A45: Presenting Partner — Count | B45: 0 | C45: 1 | D45: 1 | E45: 1 | F45: 1
A46: Presenting Partner — Revenue | B46: =B44*B45 -> 0 | C46: =C44*C45 -> 50000 | D46: =D44*D45 -> 50000 | E46: =E44*E45 -> 50000 | F46: =F44*F45 -> 50000
A48: Partner — Price | B48: 15000 | C48: 0 | D48: 15000 | E48: 15000 | F48: 15000
...

Sheet Cost
A1: COST
A3: MODEL ASSUMPTIONS
A4: Venue Contract Escalation Rate | B4: 0.03
A5: Ambition Growth Rate (Category C) | B5: 0.06
A6: Contingency % | B6: 0.09
A8: COST CATEGORY DEFINITIONS:
A9: Category A (Fixed/Contract): Costs driven by contracts or predictable obligations. Grow at contractual rate or general inflation.
A10: Category B (Guest-linked): Costs that scale with the number of ticket holders. More tickets sold = higher cost.
A11: Category C (Ambition-linked): Costs tied to the quality and ambition of the event. Default growth: Ambition Growth Rate above.
A12: Contingency: A buffer calculated as % of total costs (A+B+C) for unexpected expenses.
A14: CATEGORY A: FIXED / CONTRACT
B15: 2027 | C15: 2028 | D15: 2029 | E15: 2030 | F15: 2031 | G15: 2032 | H15: 2033 | I15: 2034 | J15: 2035 | K15: 2036
A16: Venue (Swiss House) | B16: 27951 | C16: =B16*(1+$B$4) -> 28789.53 | D16: =C16*(1+$B$4) -> 29653.216 | E16: =D16*(1+$B$4) -> 30542.812 | F16: =E16*(1+$B$4) -> 31459.097 | G16: =F16*(1+$B$4) -> 32402.87 | H16: =G16*(1+$B$4) -> 33374.956 | I16: =H16*(1+$B$4) -> 34376.204 | J16: =I16*(1+$B$4) -> 35407.491 | K16: =J16*(1+$B$4) -> 36469.715
A17: F&B Credit (guest spend vs minimums) | B17: -9000 | C17: =B17*(1+$B$4) -> -9270 | D17: =C17*(1+$B$4) -> -9548.1 | E17: =D17*(1+$B$4) -> -9834.543 | F17: =E17*(1+$B$4) -> -10129.579 | G17: =F17*(1+$B$4) -> -10433.467 | H17: =G17*(1+$B$4) -> -10746.471 | I17: =H17*(1+$B$4) -> -11068.865 | J17: =I17*(1+$B$4) -> -11400.931 | K17: =J17*(1+$B$4) -> -11742.959
A18: Insurance / Permits / Ticketing | B18: 2500 | C18: =B18*(1+'P&L'!$B$4) -> 2550 | D18: =C18*(1+'P&L'!$B$4) -> 2601 | E18: =D18*(1+'P&L'!$B$4) -> 2653.02 | F18: =E18*(1+'P&L'!$B$4) -> 2706.0804 | G18: =F18*(1+'P&L'!$B$4) -> 2760.202 | H18: =G18*(1+'P&L'!$B$4) -> 2815.406 | I18: =H18*(1+'P&L'!$B$4) -> 2871.7142 | J18: =I18*(1+'P&L'!$B$4) -> 2929.1485 | K18: =J18*(1+'P&L'!$B$4) -> 2987.7314
A19: Transport | B19: 2500 | C19: =B19*(1+'P&L'!$B$4) -> 2550 | D19: =C19*(1+'P&L'!$B$4) -> 2601 | E19: =D19*(1+'P&L'!$B$4) -> 2653.02 | F19: =E19*(1+'P&L'!$B$4) -> 2706.0804 | G19: =F19*(1+'P&L'!$B$4) -> 2760.202 | H19: =G19*(1+'P&L'!$B$4) -> 2815.406 | I19: =H19*(1+'P&L'!$B$4) -> 2871.7142 | J19: =I19*(1+'P&L'!$B$4) -> 2929.1485 | K19: =J19*(1+'P&L'!$B$4) -> 2987.7314
A20: Sunday Program (incl. GRÜEZI coffee costs) | B20: 1000 | C20: =B20*(1+'P&L'!$B$4) -> 1020 | D20: =C20*(1+'P&L'!$B$4) -> 1040.4 | E20: =D20*(1+'P&L'!$B$4) -> 1061.208 | F20: =E20*(1+'P&L'!$B$4) -> 1082.4322 | G20: =F20*(1+'P&L'!$B$4) -> 1104.0808 | H20: =G20*(1+'P&L'!$B$4) -> 1126.1624 | I20: =H20*(1+'P&L'!$B$4) -> 1148.6857 | J20: =I20*(1+'P&L'!$B$4) -> 1171.6594 | K20: =J20*(1+'P&L'!$B$4) -> 1195.0926
A22: Category A Subtotal | B22: =B16+B17+B18+B19+B20 -> 24951 | C22: =C16+C17+C18+C19+C20 -> 25639.53 | D22: =D16+D17+D18+D19+D20 -> 26347.516 | E22: =E16+E17+E18+E19+E20 -> 27075.517 | F22: =F16+F17+F18+F19+F20 -> 27824.11 | G22: =G16+G17+G18+G19+G20 -> 28593.888 | H22: =H16+H17+H18+H19+H20 -> 29385.46 | I22: =I16+I17+I18+I19+I20 -> 30199.454 | ... K22: =K16+K17+K18+K19+K20 -> 31897.312
A24: CATEGORY B: GUEST-LINKED
B25: 2027 | C25: 2028 | D25: 2029 | E25: 2030 | F25: 2031 | G25: 2032 | H25: 2033 | I25: 2034 | J25: 2035 | K25: 2036
A26: Welcome Drinks (Ticket Count × 2 × CHF 9) | B26: 4500 | C26: =Revenue!$B$5*2*9 -> 4500 | D26: =Revenue!$B$5*2*9 -> 4500 | E26: =Revenue!$B$5*2*9 -> 4500 | F26: =Revenue!$B$5*2*9 -> 4500 | G26: =Revenue!$B$5*2*9 -> 4500 | H26: =Revenue!$B$5*2*9 -> 4500 | I26: =Revenue!$B$5*2*9 -> 4500 | J26: =Revenue!$B$5*2*9 -> 4500 | K26: =Revenue!$B$5*2*9 -> 4500
A27: Security | B27: 4500 | C27: =$B$27 -> 4500 | D27: =$B$27 -> 4500 | E27: =$B$27 -> 4500 | F27: =$B$27 -> 4500 | G27: =$B$27 -> 4500 | H27: =$B$27 -> 4500 | I27: =$B$27 -> 4500 | J27: =$B$27 -> 4500 | K27: =$B$27 -> 4500
A29: Category B Subtotal | B29: =B26+B27 -> 9000 | C29: =C26+C27 -> 9000 | D29: =D26+D27 -> 9000 | E29: =E26+E27 -> 9000 | F29: =F26+F27 -> 9000 | G29: =G26+G27 -> 9000 | H29: =H26+H27 -> 9000 | I29: =I26+I27 -> 9000 | ... K29: =K26+K27 -> 9000
A31: CATEGORY C: AMBITION-LINKED
B32: 2027 | C32: 2028 | D32: 2029 | E32: 2030 | F32: 2031 | G32: 2032 | H32: 2033 | I32: 2034 | J32: 2035 | K32: 2036
A33: Talent (DJs / Artists) | B33: 18000 | C33: =B33*(1+$B$5) -> 19080 | D33: =C33*(1+$B$5) -> 20224.8 | E33: =D33*(1+$B$5) -> 21438.288 | F33: =E33*(1+$B$5) -> 22724.585 | G33: =F33*(1+$B$5) -> 24088.06 | H33: =G33*(1+$B$5) -> 25533.344 | I33: =H33*(1+$B$5) -> 27065.345 | J33: =I33*(1+$B$5) -> 28689.265 | K33: =J33*(1+$B$5) -> 30410.621
A34: Production (Sound / Lighting) | B34: 12000 | C34: =B34*(1+$B$5) -> 12720 | D34: =C34*(1+$B$5) -> 13483.2 | E34: =D34*(1+$B$5) -> 14292.192 | F34: =E34*(1+$B$5) -> 15149.724 | G34: =F34*(1+$B$5) -> 16058.707 | H34: =G34*(1+$B$5) -> 17022.229 | I34: =H34*(1+$B$5) -> 18043.563 | J34: =I34*(1+$B$5) -> 19126.177 | K34: =J34*(1+$B$5) -> 20273.748
A35: Decor / Branding | B35: 3500 | C35: =B35*(1+$B$5) -> 3710 | D35: =C35*(1+$B$5) -> 3932.6 | E35: =D35*(1+$B$5) -> 4168.556 | F35: =E35*(1+$B$5) -> 4418.6694 | G35: =F35*(1+$B$5) -> 4683.7895 | H35: =G35*(1+$B$5) -> 4964.8169 | I35: =H35*(1+$B$5) -> 5262.7059 | J35: =I35*(1+$B$5) -> 5578.4683 | K35: =J35*(1+$B$5) -> 5913.1764
A36: Photo / Video | B36: 5000 | C36: =B36*(1+$B$5) -> 5300 | D36: =C36*(1+$B$5) -> 5618 | E36: =D36*(1+$B$5) -> 5955.08 | F36: =E36*(1+$B$5) -> 6312.3848 | G36: =F36*(1+$B$5) -> 6691.1279 | H36: =G36*(1+$B$5) -> 7092.5956 | I36: =H36*(1+$B$5) -> 7518.1513 | J36: =I36*(1+$B$5) -> 7969.2404 | K36: =J36*(1+$B$5) -> 8447.3948
A37: Marketing / Print | B37: 2000 | C37: =B37*(1+$B$5) -> 2120 | D37: =C37*(1+$B$5) -> 2247.2 | E37: =D37*(1+$B$5) -> 2382.032 | F37: =E37*(1+$B$5) -> 2524.9539 | G37: =F37*(1+$B$5) -> 2676.4512 | H37: =G37*(1+$B$5) -> 2837.0382 | I37: =H37*(1+$B$5) -> 3007.2605 | J37: =I37*(1+$B$5) -> 3187.6961 | K37: =J37*(1+$B$5) -> 3378.9579
A38: Operating Partner | B38: 6000 | C38: =B38*(1+$B$5) -> 6360 | D38: =C38*(1+$B$5) -> 6741.6 | E38: =D38*(1+$B$5) -> 7146.096 | F38: =E38*(1+$B$5) -> 7574.8618 | G38: =F38*(1+$B$5) -> 8029.3535 | H38: =G38*(1+$B$5) -> 8511.1147 | I38: =H38*(1+$B$5) -> 9021.7816 | J38: =I38*(1+$B$5) -> 9563.0884 | K38: =J38*(1+$B$5) -> 10136.874
A39: Chedi Winter Garden (Friday) | B39: 2500 | C39: =B39*(1+$B$5) -> 2650 | D39: =C39*(1+$B$5) -> 2809 | E39: =D39*(1+$B$5) -> 2977.54 | F39: =E39*(1+$B$5) -> 3156.1924 | G39: =F39*(1+$B$5) -> 3345.5639 | H39: =G39*(1+$B$5) -> 3546.2978 | I39: =H39*(1+$B$5) -> 3759.0756 | J39: =I39*(1+$B$5) -> 3984.6202 | K39: =J39*(1+$B$5) -> 4223.6974
A41: Category C Subtotal | B41: =B33+B34+B35+B36+B37+B38+B39 -> 49000 | C41: =C33+C34+C35+C36+C37+C38+C39 -> 51940 | D41: =D33+D34+D35+D36+D37+D38+D39 -> 55056.4 | E41: =E33+E34+E35+E36+E37+E38+E39 -> 58359.784 | F41: =F33+F34+F35+F36+F37+F38+F39 -> 61861.371 | G41: =G33+G34+G35+G36+G37+G38+G39 -> 65573.053 | H41: =H33+H34+H35+H36+H37+H38+H39 -> 69507.437 | I41: =I33+I34+I35+I36+I37+I38+I39 -> 73677.883 | ... K41: =K33+K34+K35+K36+K37+K38+K39 -> 82784.469
A43: DIRECT COST TOTALS
B44: 2027 | C44: 2028 | D44: 2029 | E44: 2030 | F44: 2031 | G44: 2032 | H44: 2033 | I44: 2034 | J44: 2035 | K44: 2036
A45: Direct Cost Subtotal (A+B+C) | B45: =B22+B29+B41 -> 82951 | C45: =C22+C29+C41 -> 86579.53 | D45: =D22+D29+D41 -> 90403.916 | E45: =E22+E29+E41 -> 94435.301 | F45: =F22+F29+F41 -> 98685.481 | G45: =G22+G29+G41 -> 103166.94 | H45: =H22+H29+H41 -> 107892.9 | I45: =I22+I29+I41 -> 112877.34 | ... K45: =K22+K29+K41 -> 123681.78
A46: Contingency | B46: =B45*$B$6 -> 7465.59 | C46: =C45*$B$6 -> 7792.1577 | D46: =D45*$B$6 -> 8136.3524 | E46: =E45*$B$6 -> 8499.1771 | F46: =F45*$B$6 -> 8881.6933 | G46: =G45*$B$6 -> 9285.0247 | H46: =H45*$B$6 -> 9710.3606 | I46: =I45*$B$6 -> 10158.96 | ... K46: =K45*$B$6 -> 11131.36
A47: TOTAL WINTER DIRECT COST | B47: =B45+B46 -> 90416.59 | C47: =C45+C46 -> 94371.688 | D47: =D45+D46 -> 98540.268 | E47: =E45+E46 -> 102934.48 | F47: =F45+F46 -> 107567.17 | G47: =G45+G46 -> 112451.97 | H47: =H45+H46 -> 117603.26 | I47: =I45+I46 -> 123036.3 | ... K47: =K45+K46 -> 134813.14
A48: Summer Cost | B48: =IF(2027>=Revenue!$B$13,B47*Revenue!$B$12,0) -> 45208.295 | C48: =IF(2028>=Revenue!$B$13,C47*Revenue!$B$12,0) -> 47185.844 | D48: =IF(2029>=Revenue!$B$13,D47*Revenue!$B$12,0) -> 49270.134 | E48: =IF(2030>=Revenue!$B$13,E47*Revenue!$B$12,0) -> 51467.239 | F48: =IF(2031>=Revenue!$B$13,F47*Revenue!$B$12,0) -> 53783.587 | G48: =IF(2032>=Revenue!$B$13,G47*Revenue!$B$12,0) -> 56225.983 | H48: =IF(2033>=Revenue!$B$13,H47*Revenue!$B$12,0) -> 58801.628 | I48: =IF(2034>=Revenue!$B$13,I47*Revenue!$B$12,0) -> 61518.148 | J48: =IF(2035>=Revenue!$B$13,J47*Revenue!$B$12,0) -> 64383.614 | K48: =IF(2036>=Revenue!$B$13,K47*Revenue!$B$12,0) -> 67406.571
A49: TOTAL ANNUAL DIRECT COST | B49: =B47+B48 -> 135624.89 | C49: =C47+C48 -> 141557.53 | D49: =D47+D48 -> 147810.4 | E49: =E47+E48 -> 154401.72 | F49: =F47+F48 -> 161350.76 | G49: =G47+G48 -> 168677.95 | H49: =H47+H48 -> 176404.89 | I49: =I47+I48 -> 184554.44 | ... K49: =K47+K48 -> 202219.71
...
